Workbook

Sheet PRESUPUESTO DE MARKETING
L2: PRORRATEO
B3: COSTOS | G3: GASTOS | K3: VALOR MENSUAL | L3: COSTOS (65%) | M3: GASTOS (35%)
B4: FIJOS | C4: VALOR MENSUAL | G4: ADMINISTRATIVOS | H4: VALOR MENSUAL | J4: AGUA | K4: 150000 | L4: =K4*0.65 -> 97500 | M4: =K4*0.35 -> 52500
B5: NOMINA DE LOS EMPLEADOS (EQUIPO TÉCNICO) | C5: =SUM('PRESUPUESTO DE PERSONAL'!L6:L8) -> 15889095 | G5: NOMINA ADMINISTRATIVA | H5: =SUM('PRESUPUESTO DE PERSONAL'!L5, 'PRESUPUESTO DE PERSONAL'!L9) -> 7333095 | J5: LUZ | K5: 400000 | L5: =K5*0.65 -> 260000 | M5: =K5*0.35 -> 140000
B6: ARRIENDO | C6: 1800000 | G6: UTILES Y PAPELERIA | H6: 100000 | J6: INTERNET | K6: 150000 | L6: =K6*0.65 -> 97500 | M6: =K6*0.35 -> 52500
B7: DOMINIO WEB (visioptica.com) Y SSL (prorrateo mensual) | C7: 50000 | G7: GASTOS DE CAFETERIA | H7: 150000 | J7: GAS | K7: 100000 | L7: =K7*0.65 -> 65000 | M7: =K7*0.35 -> 35000
B8: SEGURO | C8: 40000 | G8: SERVICIOS LEGALES, CONTABLES Y ADMINISTRATIVOS | H8: 800000 | J8: SEGURO
B9: SUBTOTAL | C9: =SUM(C5:C8) -> 17779095 | G9: AGUA (prorrateo admin. 35%) | H9: =M4 -> 52500
B10: VARIABLES | G10: LUZ (prorrateo admin. 35%) | H10: =M5 -> 140000
B11: SERVIDORES CLOUD & HOSTING (AWS/DIGITALOCEAN) | C11: 2000000 | G11: GAS (prorrateo admin. 35%) | H11: =M7 -> 35000
B12: HERRAMIENTAS SAAS (Twilio, SendGrid, GitHub, Google Workspace) | C12: 1200000 | G12: INTERNET (prorrateo admin. 35%) | H12: =M6 -> 52500
B13: SOPORTE Y MANTENIMIENTO TÉCNICO ADICIONAL | C13: 1000000 | G13: SUBTOTAL | H13: =SUM(H5:H7) -> 7583095
B14: AGUA | C14: =L4 -> 97500 | G14: VENTAS
B15: LUZ | C15: =L5 -> 260000 | G15: NOMINA COMERCIAL | H15: ='PRESUPUESTO DE PERSONAL'!L9 -> 2273095
B16: GAS | C16: =L7 -> 65000 | G16: GASTOS DE TRANSPORTE (visitas comerciales a ópticas) | H16: 300000
B17: INTERNET | C17: =L6 -> 97500 | G17: INVERSIÓN EN MARKETING DIGITAL & CAMPAÑAS ADS (Google/Meta) | H17: 2000000
B18: SUBTOTAL | C18: =SUM(C11:C17) -> 4720000 | G18: EMPAQUES Y EMBALAJES | H18: 0
B19: COSTOS TOTALES | C19: =C9+C18 -> 22499095 | D19: =C19*12 -> 269989140 | G19: COMISIONES (2%) | H19: =E32*2% -> 915333.1
G20: SUBTOTAL | H20: =SUM(H15:H19) -> 5488428.1
G21: FINANCIEROS
G22: INTERESES CREDITO | H22: =E40 -> 160000
G23: IMPUESTO 4 X MIL | H23: =(E32-18330900)*0.4% -> 109743.02
G24: CUOTAS DE MANEJO | H24: 10000
G25: CHEQUERA | H25: 0
B26: PRESUPUESTO DE VENTAS | G26: SUBTOTAL | H26: =SUM(H22:H25) -> 279743.02
B27: PLANES / SERVICIOS | C27: PRECIO MENSUAL | D27: SUSCRIPTORES / SERVICIOS | E27: INGRESOS TOTALES | G27: GASTOS TOTALES | H27: =H13+H20+H26 -> 13351266
B28: SUSCRIPCIÓN PLAN BÁSICO | C28: 150000 | D28: 35 | E28: =C28*D28 -> 5250000
B29: SUSCRIPCIÓN PLAN PRO | C29: 260000 | D29: 60 | E29: =C29*D29 -> 15600000 | G29: GASTOS ANUALES | H29: =H27*12 -> 1.6021519e+08
B30: SUSCRIPCIÓN PLAN PREMIUM | C30: 500000 | D30: 30 | E30: =C30*D30 -> 15000000
B31: SERVICIOS ADICIONALES (Módulo Extra, Capacitación, Migración BD) | C31: 283333 | D31: 35 | E31: =C31*D31 -> 9916655 | G31: INGRESO ANUAL
B32: TOTAL DE VENTAS MENSUALES | E32: =SUM(E28:E31) -> 45766655 | G32: =E32*12 -> 549199860
C33: Nota: fila de servicios adicionales usa un precio promedio ponderado de las 3 líneas del Canvas (Módulo Extra, Capacitación e Implementación, Migración de BD)
B36: TABLA DE AMORTIZACION | G36: =J39*12 -> 4410866.2 | I36: VALOR PRESTAMO | K36: 10000000
I37: TASA DE INTERES | K37: 0.016
B38: PERIODOS | C38: CUOTA | D38: CAPITAL | E38: INTERESES | F38: SALDO | I38: PLAZO | K38: 36
B39: 0 | C39: 0 | D39: 0 | E39: 0 | F39: =K36 -> 10000000 | I39: CUOTA | J39: =PMT(K37,K38,-K36) -> 367572.18
B40: 1 | C40: =$J$39 -> 367572.18 | D40: =C40-E40 -> 207572.18 | E40: =F39*$K$37 -> 160000 | F40: =F39-D40 -> 9792427.8
B41: 2 | C41: =$J$39 -> 367572.18 | D41: =C41-E41 -> 210893.34 | E41: =F40*$K$37 -> 156678.85 | F41: =F40-D41 -> 9581534.5 | K41: TOTAL
B42: 3 | C42: =$J$39 -> 367572.18 | D42: =C42-E42 -> 214267.63 | E42: =F41*$K$37 -> 153304.55 | F42: =F41-D42 -> 9367266.9 | K42: =J39*12 -> 4410866.2
B43: 4 | C43: =$J$39 -> 367572.18 | D43: =C43-E43 -> 217695.91 | E43: =F42*$K$37 -> 149876.27 | F43: =F42-D43 -> 9149570.9
...

Sheet PRESUPUESTO DE PERSONAL
H3: DEDUCCIONES
C4: CARGOS | D4: CANTIDAD | E4: SALARIO BASICO | F4: AUXILIO DE TRANSPORTE | G4: TOTAL DEVENGADO | H4: SALUD 4% | I4: PENSION 4% | J4: FSP 1% | K4: TOTAL A PAGAR
C5: GERENTE GENERAL | D5: 1 | E5: 5500000 | F5: =IF((E5<=$E$14),249095,0) -> 0 | G5: =E5+F5 -> 5500000 | H5: =E5*4% -> 220000 | I5: =E5*4% -> 220000 | J5: =IF((E5<=$E$16),0,E5*1%) -> 0 | K5: =G5-H5-I5 -> 5060000 | L5: =K5*D5 -> 5060000 | M5: GASTO ADMINISTRATIVO
C6: LÍDER TÉCNICO (SRE) | D6: 1 | E6: 5000000 | F6: =IF((E6<=$E$14),249095,0) -> 0 | G6: =E6+F6 -> 5000000 | H6: =E6*4% -> 200000 | I6: =E6*4% -> 200000 | J6: =IF((E6<=$E$16),0,E6*1%) -> 0 | K6: =G6-H6-I6 -> 4600000 | L6: =K6*D6 -> 4600000 | M6: COSTO FIJO
C7: DESARROLLADOR SENIOR FULLSTACK | D7: 2 | E7: 5000000 | F7: =IF((E7<=$E$14),249095,0) -> 0 | G7: =E7+F7 -> 5000000 | H7: =E7*4% -> 200000 | I7: =E7*4% -> 200000 | J7: =IF((E7<=$E$16),0,E7*1%) -> 0 | K7: =G7-H7-I7 -> 4600000 | L7: =K7*D7 -> 9200000 | M7: COSTO FIJO
C8: ESPECIALISTA SOPORTE/ONBOARDING | D8: 1 | E8: 2000000 | F8: =IF((E8<=$E$14),249095,0) -> 249095 | G8: =E8+F8 -> 2249095 | H8: =E8*4% -> 80000 | I8: =E8*4% -> 80000 | J8: =IF((E8<=$E$16),0,E8*1%) -> 0 | K8: =G8-H8-I8 -> 2089095 | L8: =K8*D8 -> 2089095 | M8: COSTO FIJO
C9: EJECUTIVO DE VENTAS B2B | D9: 1 | E9: 2200000 | F9: =IF((E9<=$E$14),249095,0) -> 249095 | G9: =E9+F9 -> 2449095 | H9: =E9*4% -> 88000 | I9: =E9*4% -> 88000 | J9: =IF((E9<=$E$16),0,E9*1%) -> 0 | K9: =G9-H9-I9 -> 2273095 | L9: =K9*D9 -> 2273095 | M9: GASTO DE VENTAS
C10: TOTAL NOMINA | L10: =SUM(L5:L9) -> 23222190
D12: SMMLV 2026 | E12: 1750905
D14: 2 SMMLV | E14: =E12*2 -> 3501810
D16: 4 SMMLV | E16: =E12*4 -> 7003620
C18: Nota: salarios estimados como valores de referencia para un emprendimiento SaaS en etapa inicial (Ibagué), calibrados con las cifras del Modelo Canvas de Visioptica. No provienen de una nómina real ya definida.

Sheet INVERSION INICIAL
C4: Maquinas, Equipos y Elementos necesarios (Tangibles)
C5: Descripcion | D5: Cantidad | E5: Precio Unitario | F5: Valor Total
C6: Equipos de cómputo (equipo técnico y administrativo) | D6: 6 | E6: 2000000 | F6: =D6*E6 -> 12000000
C7: Escritorios ergonomicos | D7: 6 | E7: 400000 | F7: =D7*E7 -> 2400000
C8: Sillas ergonomicas | D8: 6 | E8: 280000 | F8: =D8*E8 -> 1680000
C9: Mesa de reuniones | D9: 1 | E9: 1130000 | F9: =D9*E9 -> 1130000
C10: Router rompemuro | D10: 1 | E10: 160000 | F10: =D10*E10 -> 160000
C11: Sofa para recepcion | D11: 1 | E11: 600000 | F11: =D11*E11 -> 600000
C12: letrero | D12: 1 | E12: 1000000 | F12: =D12*E12 -> 1000000
C13: Alformbra grande | D13: 1 | E13: 130000 | F13: =D13*E13 -> 130000
E14: Gran Total | F14: =SUM(F6:F13) -> 19100000

Sheet CAPITAL INICIAL
B3: VALOR CAPITAL INICIAL | D3: ='PRESUPUESTO DE MARKETING'!C19+'PRESUPUESTO DE MARKETING'!H27+'INVERSION INICIAL'!F14 -> 54950361 | E3: Gastos totales, Costos totales y Inversion Inicial | H3: ='PRESUPUESTO DE MARKETING'!C19+'PRESUPUESTO DE MARKETING'!H27+'INVERSION INICIAL'!F13 -> 35980361
B5: ORIGEN DE LOS FONDOS
B6: AHORROS | D6: 14807161
B7: PRESTAMOS BANCARIOS | D7: 10000000 | F7: =D3-D14 -> 143200.12
B8: PRESTAMOS PERSONALES | D8: 0
B9: PRESTAMOS DE TERCEROS | D9: 0
B10: SUBSIDIOS DEL GOBIERNO | D10: 0
B11: FONDO (EMPRENDER) | D11: 0
B12: CAPITAL SEMILLA | D12: 0
B13: INVERSIONISTAS | D13: 30000000
B14: TOTAL | D14: =SUM(D6:D13) -> 54807161

Sheet FLUJO DE EFECTIVO
F3: AÑO 1 | G3: AÑO 2 | H3: AÑO 3 | I3: AÑO 4 | J3: AÑO 5 | K3: AÑO 6
D4: INGRESOS
D5: PRESUPUESTO DE VENTAS | F5: ='PRESUPUESTO DE MARKETING'!E32*12 -> 549199860 | G5: =F5*$F$17 -> 5.8346993e+08 | H5: =G5*$F$17 -> 619878455 | I5: =H5*$F$17 -> 6.5855887e+08 | J5: =I5*$F$17 -> 6.9965294e+08 | K5: =J5*$F$17 -> 7.4331129e+08
D6: CAPITAL INICIAL | F6: ='CAPITAL INICIAL'!D3 -> 54950361 | G6: 0 | H6: 0 | I6: 0 | K6: 0
D7: TOTAL INGRESOS | E7: =SUM(E5:E6) -> 0 | F7: =SUM(F5:F6) -> 6.0415022e+08 | G7: =SUM(G5:G6) -> 5.8346993e+08 | H7: =SUM(H5:H6) -> 619878455 | I7: =SUM(I5:I6) -> 6.5855887e+08 | J7: =SUM(J5:J6) -> 6.9965294e+08 | K7: =SUM(K5:K6) -> 7.4331129e+08
D8: EGRESOS
D9: COSTOS TOTALES | F9: ='PRESUPUESTO DE MARKETING'!C19*12 -> 269989140 | G9: =F9*$F$17 -> 2.8683646e+08 | H9: =G9*$F$17 -> 3.0473506e+08 | I9: =H9*$F$17 -> 3.2375053e+08 | J9: =I9*$F$17 -> 343952558 | K9: =J9*$F$17 -> 3.654152e+08
D10: GASTOS TOTALES | F10: ='PRESUPUESTO DE MARKETING'!H27*12 -> 1.6021519e+08 | G10: =F10*$F$17 -> 1.7021262e+08 | H10: =G10*$F$17 -> 1.8083389e+08 | I10: =H10*$F$17 -> 1.9211792e+08 | J10: =I10*$F$17 -> 2.0410608e+08 | K10: =J10*$F$17 -> 2.168423e+08
D11: NOMINA PERSONAL | F11: 0
D12: CUOTA PRESTAMO | F12: ='PRESUPUESTO DE MARKETING'!J39*12 -> 4410866.2 | G12: =F12 -> 4410866.2 | H12: =G12 -> 4410866.2 | J12: =I12 | K12: =J12
D13: INVERSION ACTIVOS | F13: ='INVERSION INICIAL'!F14 -> 19100000 | G13: 0 | H13: 0 | I13: 0 | J13: 0 | K13: 0
D14: TOTAL EGRESOS | E14: =SUM(E9:E13) -> 0 | F14: =SUM(F9:F13) -> 4.537152e+08 | G14: =SUM(G9:G13) -> 461459950 | H14: =SUM(H9:H13) -> 4.8997981e+08 | I14: =SUM(I9:I13) -> 515868449 | J14: =SUM(J9:J13) -> 5.4805864e+08 | K14: =SUM(K9:K13) -> 5.822575e+08
D15: SALDO | E15: =E7-E14 -> 0 | F15: =F7-F14 -> 1.5043502e+08 | G15: =G7-G14 -> 1.2200998e+08 | H15: =H7-H14 -> 1.2989864e+08 | I15: =I7-I14 -> 1.4269042e+08 | J15: =J7-J14 -> 1.515943e+08 | K15: =K7-K14 -> 1.6105379e+08
D17: Factor de Inflación | F17: =1+0.0624 -> 1.0624
